Workbook

Sheet Setup
A1: Covered Calls ledger: setup
A3: Last app sync | C3: The app writes this timestamp every time it syncs.
A5: Connect
A6: 1 | B6: Import this file into Google Sheets (File > Import > Upload, or open it in Drive and choose File > Save as Google Sheets).
A7: 2 | B7: Copy the Sheet ID from the URL: the long code between /d/ and /edit. Pasting the whole URL into the app also works.
A8: 3 | B8: In the app, open Settings > Google Sheet. It shows the app's service account email. Share this sheet with that email as an Editor.
A9: 4 | B9: Paste the Sheet ID and press Connect. New trades, closes and price updates then sync automatically.
A11: What the app writes
A12: Transactions | B12: Appends one row per fill into columns A:I and K:M, plus the Lot ID in O. Column J (cash) and N (Schwab check) are formulas; leave them.
A13: Lots | B13: Adds each new Lot ID in column A. Everything else on Lots is formulas, except K (price override).
A14: Positions | B14: Adds the Position ID in column A for new positions and updates live inputs K:O (stock price, call mark, GTC, stoplight, time).
A15: Setup | B15: Writes the last sync time in B3.
A16: Rule | B16: Keep tab names and column order as they are. Add your own tabs or columns to the right freely.
A18: Legend
A19: Blue text | B19: Inputs: typed by you or written by the app.
A20: Black text | B20: Formulas. Do not overwrite.
A21: Yellow fill | B21: Assumptions to set yourself (tax year, tax rates).
A23: Actions | B23: Buy shares, Sell shares, Sell call, Buy to close, Expired, Assigned. Quantity sign: + for buys, - for sells (shares in shares, calls in contracts).
A24: Called away | B24: Record two rows: Assigned (call, +contracts, price 0) and Sell shares (-shares at the strike). Put the delivered lot's ID on the Sell shares row.
A25: Lots | B25: Every row carries a Lot ID. A lot is one purchase of shares; calls and closes on those shares use the same Lot ID. Effective cost = cost minus premium kept on that lot.
A26: Live prices | B26: In Google Sheets you can type =GOOGLEFINANCE(B2) into Lots column K to price free lots automatically.
A27: Tax note | B27: Premium from calls that expire or are bought back is a short-term gain when the call closes. If assigned, it is added to the share sale price. Estimates only, not tax advice.

Sheet Summary
A1: Covered Calls: summary
A3: Tax year | B3: 2026 | C3: Set the year to report.
A4: Year starts | B4: =DATE(B3,1,1) -> 46023
A5: Next year starts | B5: =DATE(B3+1,1,1) -> 46388
A7: Federal marginal rate | B7: 0.24 | C7: Placeholder. Set your own federal bracket.
A8: California rate | B8: 0.093 | C8: Placeholder. California taxes gains as ordinary income.
A9: Add 3.8% NIIT? | B9: No | C9: Yes if your income is over the net investment income tax threshold.
A10: Combined rate | B10: =B7+B8+IF(B9="Yes",0.038,0) -> 0.333
A12: Realized this year
A13: Premium collected (calls sold this year) | B13: =SUMIFS(Transactions!$J:$J,Transactions!$B:$B,"Sell call",Transactions!$A:$A,">="&B4,Transactions!$A:$A,"<"&B5) -> 55 | C13: All calls sold, open or closed.
A14: Buy backs paid this year | B14: =-SUMIFS(Transactions!$J:$J,Transactions!$B:$B,"Buy to close",Transactions!$A:$A,">="&B4,Transactions!$A:$A,"<"&B5) -> 0
A15: Realized premium (closed positions) | B15: =SUMIFS(Positions!$V:$V,Positions!$U:$U,">="&B4,Positions!$U:$U,"<"&B5) -> 0 | C15: Premium minus buy back, for positions closed this year.
A16: Realized stock gains (called away) | B16: =SUMIFS(Lots!$R:$R,Lots!$S:$S,">="&B4,Lots!$S:$S,"<"&B5) -> 0 | C16: Sale price minus the cost of the lot actually delivered.
A17: Realized total | B17: =B15+B16 -> 0
A18: Est. tax on realized premium | B18: =MAX(0,B15)*B10 -> 0
A19: Est. tax on realized total | B19: =MAX(0,B17)*B10 -> 0
A21: Open right now
A22: Open positions | B22: =COUNTIF(Positions!$C:$C,"Open") -> 1
A23: Share cost used | B23: =SUMIFS(Positions!$H:$H,Positions!$C:$C,"Open") -> 2780
A24: Premium collected | B24: =SUMIFS(Positions!$I:$I,Positions!$C:$C,"Open") -> 55
A25: Buy back all calls now | B25: =SUM(Positions!$P:$P) -> 57
A26: Premium kept if closed now | B26: =SUM(Positions!$Q:$Q) -> -2
A27: If you closed everything | B27: =SUM(Positions!$S:$S) -> -4.5 | C27: Shares plus calls, at the live prices on Positions.
A28: Account health | B28: =IF(SUMIFS(Positions!$H:$H,Positions!$T:$T,"<>")=0,"",(SUM(Positions!$R:$R)+B26)/SUMIFS(Positions!$H:$H,Positions!$T:$T,"<>")) -> 0.99838129 | C28: Share value plus premium kept, vs. share cost. 100% is even.
A29: Est. tax on open premium if closed now | B29: =MAX(0,B26)*B10 -> 0 | C29: Not owed until each call closes.
A31: Year to date
A32: Realized + open, before tax | B32: =B17+B27 -> -4.5
A33: After est. tax | B33: =B32-MAX(0,B32)*B10 -> -4.5
A34: Return on open share cost | B34: =IF(B23=0,"",B32/B23) -> -0.001618705
A36: Shares (all lots)
A37: Shares held | B37: =SUM(Lots!$G:$G) -> 100
A38: Paid for shares held | B38: =SUM(Lots!$T:$T) -> 2780
A39: Worth now | B39: =SUM(Lots!$M:$M) -> 2777.5 | C39: Uses Lots column L: live price from Positions, or your override.
A40: Up or down vs. cost | B40: =SUM(Lots!$N:$N) -> -2.5
A41: Lots under cost | B41: =COUNTIF(Lots!$N:$N,"<0") -> 1 | C41: Hold these, or only sell calls at or above their effective cost.
A42: Free lots (no call) | B42: =COUNTIF(Lots!$O:$O,"Free") -> 0

Sheet Transactions
A1: Date | B1: Action | C1: Symbol | D1: Position ID | E1: Qty | F1: Strike | G1: Expiry | H1: Price | I1: Fees | J1: Cash +/- | K1: Source | L1: Note | M1: Txn ID | N1: In Schwab export? | O1: Lot ID
A2: 46286 | B2: Buy shares | C2: PFE | D2: pfe-28-2026-10-16 | E2: 100 | H2: 27.8 | I2: 0 | J2: =IF(C2="","",-E2*H2*IF(OR(B2="Sell call",B2="Buy to close",B2="Expired",B2="Assigned"),100,1)-I2) -> -2780 | K2: Manual | L2: First covered call test trade | M2: pfe-28-2026-10-16:open-shares | N2: =IF(A2="","",IF(COUNTIFS(Reconcile!$I:$I,A2,Reconcile!$H:$H,">="&(J2-0.01),Reconcile!$H:$H,"<="&(J2+0.01))>0,"Yes","Not yet")) -> Not yet | O2: pfe-a
A3: 46286 | B3: Sell call | C3: PFE | D3: pfe-28-2026-10-16 | E3: -1 | F3: 28 | G3: 46311 | H3: 0.55 | I3: 0 | J3: =IF(C3="","",-E3*H3*IF(OR(B3="Sell call",B3="Buy to close",B3="Expired",B3="Assigned"),100,1)-I3) -> 55 | K3: Manual | L3: Oct 16 $28 call | M3: pfe-28-2026-10-16:open-call | N3: =IF(A3="","",IF(COUNTIFS(Reconcile!$I:$I,A3,Reconcile!$H:$H,">="&(J3-0.01),Reconcile!$H:$H,"<="&(J3+0.01))>0,"Yes","Not yet")) -> Not yet | O3: pfe-a
J4: =IF(C4="","",-E4*H4*IF(OR(B4="Sell call",B4="Buy to close",B4="Expired",B4="Assigned"),100,1)-I4) | N4: =IF(A4="","",IF(COUNTIFS(Reconcile!$I:$I,A4,Reconcile!$H:$H,">="&(J4-0.01),Reconcile!$H:$H,"<="&(J4+0.01))>0,"Yes","Not yet"))
J5: =IF(C5="","",-E5*H5*IF(OR(B5="Sell call",B5="Buy to close",B5="Expired",B5="Assigned"),100,1)-I5) | N5: =IF(A5="","",IF(COUNTIFS(Reconcile!$I:$I,A5,Reconcile!$H:$H,">="&(J5-0.01),Reconcile!$H:$H,"<="&(J5+0.01))>0,"Yes","Not yet"))
J6: =IF(C6="","",-E6*H6*IF(OR(B6="Sell call",B6="Buy to close",B6="Expired",B6="Assigned"),100,1)-I6) | N6: =IF(A6="","",IF(COUNTIFS(Reconcile!$I:$I,A6,Reconcile!$H:$H,">="&(J6-0.01),Reconcile!$H:$H,"<="&(J6+0.01))>0,"Yes","Not yet"))
J7: =IF(C7="","",-E7*H7*IF(OR(B7="Sell call",B7="Buy to close",B7="Expired",B7="Assigned"),100,1)-I7) | N7: =IF(A7="","",IF(COUNTIFS(Reconcile!$I:$I,A7,Reconcile!$H:$H,">="&(J7-0.01),Reconcile!$H:$H,"<="&(J7+0.01))>0,"Yes","Not yet"))
J8: =IF(C8="","",-E8*H8*IF(OR(B8="Sell call",B8="Buy to close",B8="Expired",B8="Assigned"),100,1)-I8) | N8: =IF(A8="","",IF(COUNTIFS(Reconcile!$I:$I,A8,Reconcile!$H:$H,">="&(J8-0.01),Reconcile!$H:$H,"<="&(J8+0.01))>0,"Yes","Not yet"))
J9: =IF(C9="","",-E9*H9*IF(OR(B9="Sell call",B9="Buy to close",B9="Expired",B9="Assigned"),100,1)-I9) | N9: =IF(A9="","",IF(COUNTIFS(Reconcile!$I:$I,A9,Reconcile!$H:$H,">="&(J9-0.01),Reconcile!$H:$H,"<="&(J9+0.01))>0,"Yes","Not yet"))
J10: =IF(C10="","",-E10*H10*IF(OR(B10="Sell call",B10="Buy to close",B10="Expired",B10="Assigned"),100,1)-I10) | N10: =IF(A10="","",IF(COUNTIFS(Reconcile!$I:$I,A10,Reconcile!$H:$H,">="&(J10-0.01),Reconcile!$H:$H,"<="&(J10+0.01))>0,"Yes","Not yet"))
J11: =IF(C11="","",-E11*H11*IF(OR(B11="Sell call",B11="Buy to close",B11="Expired",B11="Assigned"),100,1)-I11) | N11: =IF(A11="","",IF(COUNTIFS(Reconcile!$I:$I,A11,Reconcile!$H:$H,">="&(J11-0.01),Reconcile!$H:$H,"<="&(J11+0.01))>0,"Yes","Not yet"))
J12: =IF(C12="","",-E12*H12*IF(OR(B12="Sell call",B12="Buy to close",B12="Expired",B12="Assigned"),100,1)-I12) | N12: =IF(A12="","",IF(COUNTIFS(Reconcile!$I:$I,A12,Reconcile!$H:$H,">="&(J12-0.01),Reconcile!$H:$H,"<="&(J12+0.01))>0,"Yes","Not yet"))
J13: =IF(C13="","",-E13*H13*IF(OR(B13="Sell call",B13="Buy to close",B13="Expired",B13="Assigned"),100,1)-I13) | N13: =IF(A13="","",IF(COUNTIFS(Reconcile!$I:$I,A13,Reconcile!$H:$H,">="&(J13-0.01),Reconcile!$H:$H,"<="&(J13+0.01))>0,"Yes","Not yet"))
J14: =IF(C14="","",-E14*H14*IF(OR(B14="Sell call",B14="Buy to close",B14="Expired",B14="Assigned"),100,1)-I14) | N14: =IF(A14="","",IF(COUNTIFS(Reconcile!$I:$I,A14,Reconcile!$H:$H,">="&(J14-0.01),Reconcile!$H:$H,"<="&(J14+0.01))>0,"Yes","Not yet"))
J15: =IF(C15="","",-E15*H15*IF(OR(B15="Sell call",B15="Buy to close",B15="Expired",B15="Assigned"),100,1)-I15) | N15: =IF(A15="","",IF(COUNTIFS(Reconcile!$I:$I,A15,Reconcile!$H:$H,">="&(J15-0.01),Reconcile!$H:$H,"<="&(J15+0.01))>0,"Yes","Not yet"))
... J1000: =IF(C1000="","",-E1000*H1000*IF(OR(B1000="Sell call",B1000="Buy to close",B1000="Expired",B1000="Assigned"),100,1)-I1000) | N1000: =IF(A1000="","",IF(COUNTIFS(Reconcile!$I:$I,A1000,Reconcile!$H:$H,">="&(J1000-0.01),Reconcile!$H:$H,"<="&(J1000+0.01))>0,"Yes","Not yet"))

Sheet Lots
A1: Lot ID | B1: Symbol | C1: Bought | D1: Shares bought | E1: Cost / share | F1: Shares sold | G1: Shares held | H1: Premium kept (net) | I1: Effective cost / share | J1: Price (from Positions) | K1: Price override | L1: Price used | M1: Worth now | N1: Up / down vs. cost | O1: Status | P1: Lowest strike to sell | Q1: Wash-sale watch | R1: Realized stock gain | S1: Last sold | T1: Cost of shares held
A2: pfe-a | B2: =IF($A2="","",IFERROR(INDEX(Transactions!$C:$C,MATCH($A2,Transactions!$O:$O,0)),"")) -> PFE | C2: =IF($A2="","",IF(COUNTIFS(Transactions!$O:$O,$A2,Transactions!$B:$B,"Buy shares")=0,"",_xlfn.MINIFS(Transactions!$A:$A,Transactions!$O:$O,$A2,Transactions!$B:$B,"Buy shares"))) -> 46286 | D2: =IF($A2="","",SUMIFS(Transactions!$E:$E,Transactions!$O:$O,$A2,Transactions!$B:$B,"Buy shares")) -> 100 | E2: =IF($A2="","",IF(D2=0,"",-SUMIFS(Transactions!$J:$J,Transactions!$O:$O,$A2,Transactions!$B:$B,"Buy shares")/D2)) -> 27.8 | F2: =IF($A2="","",-SUMIFS(Transactions!$E:$E,Transactions!$O:$O,$A2,Transactions!$B:$B,"Sell shares")) -> 0 | G2: =IF($A2="","",D2-F2) -> 100 | H2: =IF($A2="","",SUMIFS(Transactions!$J:$J,Transactions!$O:$O,$A2,Transactions!$B:$B,"Sell call")+SUMIFS(Transactions!$J:$J,Transactions!$O:$O,$A2,Transactions!$B:$B,"Buy to close")) -> 55 | I2: =IF(OR($A2="",E2=""),"",E2-H2/D2) -> 27.25 | J2: =IF($A2="","",IFERROR(INDEX(Positions!$K:$K,MATCH(B2,Positions!$B:$B,0)),"")) -> 27.775 | L2: =IF($A2="","",IF(K2<>"",K2,J2)) -> 27.775 | M2: =IF(OR($A2="",L2=""),"",L2*G2) -> 2777.5 | N2: =IF(OR(M2="",E2=""),"",(L2-E2)*G2) -> -2.5 | O2: =IF($A2="","",IF(G2<=0,"Sold",IF((-SUMIFS(Transactions!$E:$E,Transactions!$O:$O,$A2,Transactions!$B:$B,"Sell call")-SUMIFS(Transactions!$E:$E,Transactions!$O:$O,$A2,Transactions!$B:$B,"Buy to close")-SUMIFS(Transactions!$E:$E,Transactions!$O:$O,$A2,Transactions!$B:$B,"Expired")-SUMIFS(Transactions!$E:$E,Transactions!$O:$O,$A2,Transactions!$B:$B,"Assigned"))>0,"Covered","Free"))) -> Covered | P2: =IF(OR(I2="",G2<=0),"",CEILING(MAX(I2,N(L2)),IF(E2<50,0.5,IF(E2<200,1,5)))) -> 28 | Q2: =IF(OR(N2="",G2<=0),"",IF(N2>=0,"",IF(COUNTIFS($B:$B,B2,$C:$C,">="&(TODAY()-30),$C:$C,"<="&TODAY(),$A:$A,"<>"&$A2)>0,"Loss sale now = wash sale","OK to harvest loss"))) -> OK to harvest loss | R2: =IF(OR($A2="",N(F2)<=0),"",SUMIFS(Transactions!$J:$J,Transactions!$O:$O,$A2,Transactions!$B:$B,"Sell shares")-E2*F2) | S2: =IF(OR($A2="",N(F2)<=0),"",_xlfn.MAXIFS(Transactions!$A:$A,Transactions!$O:$O,$A2,Transactions!$B:$B,"Sell shares")) | T2: =IF(OR($A2="",E2=""),"",E2*G2) -> 2780
B3: =IF($A3="","",IFERROR(INDEX(Transactions!$C:$C,MATCH($A3,Transactions!$O:$O,0)),"")) | C3: =IF($A3="","",IF(COUNTIFS(Transactions!$O:$O,$A3,Transactions!$B:$B,"Buy shares")=0,"",_xlfn.MINIFS(Transactions!$A:$A,Transactions!$O:$O,$A3,Transactions!$B:$B,"Buy shares"))) | D3: =IF($A3="","",SUMIFS(Transactions!$E:$E,Transactions!$O:$O,$A3,Transactions!$B:$B,"Buy shares")) | E3: =IF($A3="","",IF(D3=0,"",-SUMIFS(Transactions!$J:$J,Transactions!$O:$O,$A3,Transactions!$B:$B,"Buy shares")/D3)) | F3: =IF($A3="","",-SUMIFS(Transactions!$E:$E,Transactions!$O:$O,$A3,Transactions!$B:$B,"Sell shares")) | G3: =IF($A3="","",D3-F3) | H3: =IF($A3="","",SUMIFS(Transactions!$J:$J,Transactions!$O:$O,$A3,Transactions!$B:$B,"Sell call")+SUMIFS(Transactions!$J:$J,Transactions!$O:$O,$A3,Transactions!$B:$B,"Buy to close")) | I3: =IF(OR($A3="",E3=""),"",E3-H3/D3) | J3: =IF($A3="","",IFERROR(INDEX(Positions!$K:$K,MATCH(B3,Positions!$B:$B,0)),"")) | L3: =IF($A3="","",IF(K3<>"",K3,J3)) | M3: =IF(OR($A3="",L3=""),"",L3*G3) | N3: =IF(OR(M3="",E3=""),"",(L3-E3)*G3) | O3: =IF($A3="","",IF(G3<=0,"Sold",IF((-SUMIFS(Transactions!$E:$E,Transactions!$O:$O,$A3,Transactions!$B:$B,"Sell call")-SUMIFS(Transactions!$E:$E,Transactions!$O:$O,$A3,Transactions!$B:$B,"Buy to close")-SUMIFS(Transactions!$E:$E,Transactions!$O:$O,$A3,Transactions!$B:$B,"Expired")-SUMIFS(Transactions!$E:$E,Transactions!$O:$O,$A3,Transactions!$B:$B,"Assigned"))>0,"Covered","Free"))) | P3: =IF(OR(I3="",G3<=0),"",CEILING(MAX(I3,N(L3)),IF(E3<50,0.5,IF(E3<200,1,5)))) | Q3: =IF(OR(N3="",G3<=0),"",IF(N3>=0,"",IF(COUNTIFS($B:$B,B3,$C:$C,">="&(TODAY()-30),$C:$C,"<="&TODAY(),$A:$A,"<>"&$A3)>0,"Loss sale now = wash sale","OK to harvest loss"))) | R3: =IF(OR($A3="",N(F3)<=0),"",SUMIFS(Transactions!$J:$J,Transactions!$O:$O,$A3,Transactions!$B:$B,"Sell shares")-E3*F3) | S3: =IF(OR($A3="",N(F3)<=0),"",_xlfn.MAXIFS(Transactions!$A:$A,Transactions!$O:$O,$A3,Transactions!$B:$B,"Sell shares")) | T3: =IF(OR($A3="",E3=""),"",E3*G3)
B4: =IF($A4="","",IFERROR(INDEX(Transactions!$C:$C,MATCH($A4,Transactions!$O:$O,0)),"")) | C4: =IF($A4="","",IF(COUNTIFS(Transactions!$O:$O,$A4,Transactions!$B:$B,"Buy shares")=0,"",_xlfn.MINIFS(Transactions!$A:$A,Transactions!$O:$O,$A4,Transactions!$B:$B,"Buy shares"))) | D4: =IF($A4="","",SUMIFS(Transactions!$E:$E,Transactions!$O:$O,$A4,Transactions!$B:$B,"Buy shares")) | E4: =IF($A4="","",IF(D4=0,"",-SUMIFS(Transactions!$J:$J,Transactions!$O:$O,$A4,Transactions!$B:$B,"Buy shares")/D4)) | F4: =IF($A4="","",-SUMIFS(Transactions!$E:$E,Transactions!$O:$O,$A4,Transactions!$B:$B,"Sell shares")) | G4: =IF($A4="","",D4-F4) | H4: =IF($A4="","",SUMIFS(Transactions!$J:$J,Transactions!$O:$O,$A4,Transactions!$B:$B,"Sell call")+SUMIFS(Transactions!$J:$J,Transactions!$O:$O,$A4,Transactions!$B:$B,"Buy to close")) | I4: =IF(OR($A4="",E4=""),"",E4-H4/D4) | J4: =IF($A4="","",IFERROR(INDEX(Positions!$K:$K,MATCH(B4,Positions!$B:$B,0)),"")) | L4: =IF($A4="","",IF(K4<>"",K4,J4)) | M4: =IF(OR($A4="",L4=""),"",L4*G4) | N4: =IF(OR(M4="",E4=""),"",(L4-E4)*G4) | O4: =IF($A4="","",IF(G4<=0,"Sold",IF((-SUMIFS(Transactions!$E:$E,Transactions!$O:$O,$A4,Transactions!$B:$B,"Sell call")-SUMIFS(Transactions!$E:$E,Transactions!$O:$O,$A4,Transactions!$B:$B,"Buy to close")-SUMIFS(Transactions!$E:$E,Transactions!$O:$O,$A4,Transactions!$B:$B,"Expired")-SUMIFS(Transactions!$E:$E,Transactions!$O:$O,$A4,Transactions!$B:$B,"Assigned"))>0,"Covered","Free"))) | P4: =IF(OR(I4="",G4<=0),"",CEILING(MAX(I4,N(L4)),IF(E4<50,0.5,IF(E4<200,1,5)))) | Q4: =IF(OR(N4="",G4<=0),"",IF(N4>=0,"",IF(COUNTIFS($B:$B,B4,$C:$C,">="&(TODAY()-30),$C:$C,"<="&TODAY(),$A:$A,"<>"&$A4)>0,"Loss sale now = wash sale","OK to harvest loss"))) | R4: =IF(OR($A4="",N(F4)<=0),"",SUMIFS(Transactions!$J:$J,Transactions!$O:$O,$A4,Transactions!$B:$B,"Sell shares")-E4*F4) | S4: =IF(OR($A4="",N(F4)<=0),"",_xlfn.MAXIFS(Transactions!$A:$A,Transactions!$O:$O,$A4,Transactions!$B:$B,"Sell shares")) | T4: =IF(OR($A4="",E4=""),"",E4*G4)
B5: =IF($A5="","",IFERROR(INDEX(Transactions!$C:$C,MATCH($A5,Transactions!$O:$O,0)),"")) | C5: =IF($A5="","",IF(COUNTIFS(Transactions!$O:$O,$A5,Transactions!$B:$B,"Buy shares")=0,"",_xlfn.MINIFS(Transactions!$A:$A,Transactions!$O:$O,$A5,Transactions!$B:$B,"Buy shares"))) | D5: =IF($A5="","",SUMIFS(Transactions!$E:$E,Transactions!$O:$O,$A5,Transactions!$B:$B,"Buy shares")) | E5: =IF($A5="","",IF(D5=0,"",-SUMIFS(Transactions!$J:$J,Transactions!$O:$O,$A5,Transactions!$B:$B,"Buy shares")/D5)) | F5: =IF($A5="","",-SUMIFS(Transactions!$E:$E,Transactions!$O:$O,$A5,Transactions!$B:$B,"Sell shares")) | G5: =IF($A5="","",D5-F5) | H5: =IF($A5="","",SUMIFS(Transactions!$J:$J,Transactions!$O:$O,$A5,Transactions!$B:$B,"Sell call")+SUMIFS(Transactions!$J:$J,Transactions!$O:$O,$A5,Transactions!$B:$B,"Buy to close")) | I5: =IF(OR($A5="",E5=""),"",E5-H5/D5) | J5: =IF($A5="","",IFERROR(INDEX(Positions!$K:$K,MATCH(B5,Positions!$B:$B,0)),"")) | L5: =IF($A5="","",IF(K5<>"",K5,J5)) | M5: =IF(OR($A5="",L5=""),"",L5*G5) | N5: =IF(OR(M5="",E5=""),"",(L5-E5)*G5) | O5: =IF($A5="","",IF(G5<=0,"Sold",IF((-SUMIFS(Transactions!$E:$E,Transactions!$O:$O,$A5,Transactions!$B:$B,"Sell call")-SUMIFS(Transactions!$E:$E,Transactions!$O:$O,$A5,Transactions!$B:$B,"Buy to close")-SUMIFS(Transactions!$E:$E,Transactions!$O:$O,$A5,Transactions!$B:$B,"Expired")-SUMIFS(Transactions!$E:$E,Transactions!$O:$O,$A5,Transactions!$B:$B,"Assigned"))>0,"Covered","Free"))) | P5: =IF(OR(I5="",G5<=0),"",CEILING(MAX(I5,N(L5)),IF(E5<50,0.5,IF(E5<200,1,5)))) | Q5: =IF(OR(N5="",G5<=0),"",IF(N5>=0,"",IF(COUNTIFS($B:$B,B5,$C:$C,">="&(TODAY()-30),$C:$C,"<="&TODAY(),$A:$A,"<>"&$A5)>0,"Loss sale now = wash sale","OK to harvest loss"))) | R5: =IF(OR($A5="",N(F5)<=0),"",SUMIFS(Transactions!$J:$J,Transactions!$O:$O,$A5,Transactions!$B:$B,"Sell shares")-E5*F5) | S5: =IF(OR($A5="",N(F5)<=0),"",_xlfn.MAXIFS(Transactions!$A:$A,Transactions!$O:$O,$A5,Transactions!$B:$B,"Sell shares")) | T5: =IF(OR($A5="",E5=""),"",E5*G5)
B6: =IF($A6="","",IFERROR(INDEX(Transactions!$C:$C,MATCH($A6,Transactions!$O:$O,0)),"")) | C6: =IF($A6="","",IF(COUNTIFS(Transactions!$O:$O,$A6,Transactions!$B:$B,"Buy shares")=0,"",_xlfn.MINIFS(Transactions!$A:$A,Transactions!$O:$O,$A6,Transactions!$B:$B,"Buy shares"))) | D6: =IF($A6="","",SUMIFS(Transactions!$E:$E,Transactions!$O:$O,$A6,Transactions!$B:$B,"Buy shares")) | E6: =IF($A6="","",IF(D6=0,"",-SUMIFS(Transactions!$J:$J,Transactions!$O:$O,$A6,Transactions!$B:$B,"Buy shares")/D6)) | F6: =IF($A6="","",-SUMIFS(Transactions!$E:$E,Transactions!$O:$O,$A6,Transactions!$B:$B,"Sell shares")) | G6: =IF($A6="","",D6-F6) | H6: =IF($A6="","",SUMIFS(Transactions!$J:$J,Transactions!$O:$O,$A6,Transactions!$B:$B,"Sell call")+SUMIFS(Transactions!$J:$J,Transactions!$O:$O,$A6,Transactions!$B:$B,"Buy to close")) | I6: =IF(OR($A6="",E6=""),"",E6-H6/D6) | J6: =IF($A6="","",IFERROR(INDEX(Positions!$K:$K,MATCH(B6,Positions!$B:$B,0)),"")) | L6: =IF($A6="","",IF(K6<>"",K6,J6)) | M6: =IF(OR($A6="",L6=""),"",L6*G6) | N6: =IF(OR(M6="",E6=""),"",(L6-E6)*G6) | O6: =IF($A6="","",IF(G6<=0,"Sold",IF((-SUMIFS(Transactions!$E:$E,Transactions!$O:$O,$A6,Transactions!$B:$B,"Sell call")-SUMIFS(Transactions!$E:$E,Transactions!$O:$O,$A6,Transactions!$B:$B,"Buy to close")-SUMIFS(Transactions!$E:$E,Transactions!$O:$O,$A6,Transactions!$B:$B,"Expired")-SUMIFS(Transactions!$E:$E,Transactions!$O:$O,$A6,Transactions!$B:$B,"Assigned"))>0,"Covered","Free"))) | P6: =IF(OR(I6="",G6<=0),"",CEILING(MAX(I6,N(L6)),IF(E6<50,0.5,IF(E6<200,1,5)))) | Q6: =IF(OR(N6="",G6<=0),"",IF(N6>=0,"",IF(COUNTIFS($B:$B,B6,$C:$C,">="&(TODAY()-30),$C:$C,"<="&TODAY(),$A:$A,"<>"&$A6)>0,"Loss sale now = wash sale","OK to harvest loss"))) | R6: =IF(OR($A6="",N(F6)<=0),"",SUMIFS(Transactions!$J:$J,Transactions!$O:$O,$A6,Transactions!$B:$B,"Sell shares")-E6*F6) | S6: =IF(OR($A6="",N(F6)<=0),"",_xlfn.MAXIFS(Transactions!$A:$A,Transactions!$O:$O,$A6,Transactions!$B:$B,"Sell shares")) | T6: =IF(OR($A6="",E6=""),"",E6*G6)
B7: =IF($A7="","",IFERROR(INDEX(Transactions!$C:$C,MATCH($A7,Transactions!$O:$O,0)),"")) | C7: =IF($A7="","",IF(COUNTIFS(Transactions!$O:$O,$A7,Transactions!$B:$B,"Buy shares")=0,"",_xlfn.MINIFS(Transactions!$A:$A,Transactions!$O:$O,$A7,Transactions!$B:$B,"Buy shares"))) | D7: =IF($A7="","",SUMIFS(Transactions!$E:$E,Transactions!$O:$O,$A7,Transactions!$B:$B,"Buy shares")) | E7: =IF($A7="","",IF(D7=0,"",-SUMIFS(Transactions!$J:$J,Transactions!$O:$O,$A7,Transactions!$B:$B,"Buy shares")/D7)) | F7: =IF($A7="","",-SUMIFS(Transactions!$E:$E,Transactions!$O:$O,$A7,Transactions!$B:$B,"Sell shares")) | G7: =IF($A7="","",D7-F7) | H7: =IF($A7="","",SUMIFS(Transactions!$J:$J,Transactions!$O:$O,$A7,Transactions!$B:$B,"Sell call")+SUMIFS(Transactions!$J:$J,Transactions!$O:$O,$A7,Transactions!$B:$B,"Buy to close")) | I7: =IF(OR($A7="",E7=""),"",E7-H7/D7) | J7: =IF($A7="","",IFERROR(INDEX(Positions!$K:$K,MATCH(B7,Positions!$B:$B,0)),"")) | L7: =IF($A7="","",IF(K7<>"",K7,J7)) | M7: =IF(OR($A7="",L7=""),"",L7*G7) | N7: =IF(OR(M7="",E7=""),"",(L7-E7)*G7) | O7: =IF($A7="","",IF(G7<=0,"Sold",IF((-SUMIFS(Transactions!$E:$E,Transactions!$O:$O,$A7,Transactions!$B:$B,"Sell call")-SUMIFS(Transactions!$E:$E,Transactions!$O:$O,$A7,Transactions!$B:$B,"Buy to close")-SUMIFS(Transactions!$E:$E,Transactions!$O:$O,$A7,Transactions!$B:$B,"Expired")-SUMIFS(Transactions!$E:$E,Transactions!$O:$O,$A7,Transactions!$B:$B,"Assigned"))>0,"Covered","Free"))) | P7: =IF(OR(I7="",G7<=0),"",CEILING(MAX(I7,N(L7)),IF(E7<50,0.5,IF(E7<200,1,5)))) | Q7: =IF(OR(N7="",G7<=0),"",IF(N7>=0,"",IF(COUNTIFS($B:$B,B7,$C:$C,">="&(TODAY()-30),$C:$C,"<="&TODAY(),$A:$A,"<>"&$A7)>0,"Loss sale now = wash sale","OK to harvest loss"))) | R7: =IF(OR($A7="",N(F7)<=0),"",SUMIFS(Transactions!$J:$J,Transactions!$O:$O,$A7,Transactions!$B:$B,"Sell shares")-E7*F7) | S7: =IF(OR($A7="",N(F7)<=0),"",_xlfn.MAXIFS(Transactions!$A:$A,Transactions!$O:$O,$A7,Transactions!$B:$B,"Sell shares")) | T7: =IF(OR($A7="",E7=""),"",E7*G7)
B8: =IF($A8="","",IFERROR(INDEX(Transactions!$C:$C,MATCH($A8,Transactions!$O:$O,0)),"")) | C8: =IF($A8="","",IF(COUNTIFS(Transactions!$O:$O,$A8,Transactions!$B:$B,"Buy shares")=0,"",_xlfn.MINIFS(Transactions!$A:$A,Transactions!$O:$O,$A8,Transactions!$B:$B,"Buy shares"))) | D8: =IF($A8="","",SUMIFS(Transactions!$E:$E,Transactions!$O:$O,$A8,Transactions!$B:$B,"Buy shares")) | E8: =IF($A8="","",IF(D8=0,"",-SUMIFS(Transactions!$J:$J,Transactions!$O:$O,$A8,Transactions!$B:$B,"Buy shares")/D8)) | F8: =IF($A8="","",-SUMIFS(Transactions!$E:$E,Transactions!$O:$O,$A8,Transactions!$B:$B,"Sell shares")) | G8: =IF($A8="","",D8-F8) | H8: =IF($A8="","",SUMIFS(Transactions!$J:$J,Transactions!$O:$O,$A8,Transactions!$B:$B,"Sell call")+SUMIFS(Transactions!$J:$J,Transactions!$O:$O,$A8,Transactions!$B:$B,"Buy to close")) | I8: =IF(OR($A8="",E8=""),"",E8-H8/D8) | J8: =IF($A8="","",IFERROR(INDEX(Positions!$K:$K,MATCH(B8,Positions!$B:$B,0)),"")) | L8: =IF($A8="","",IF(K8<>"",K8,J8)) | M8: =IF(OR($A8="",L8=""),"",L8*G8) | N8: =IF(OR(M8="",E8=""),"",(L8-E8)*G8) | O8: =IF($A8="","",IF(G8<=0,"Sold",IF((-SUMIFS(Transactions!$E:$E,Transactions!$O:$O,$A8,Transactions!$B:$B,"Sell call")-SUMIFS(Transactions!$E:$E,Transactions!$O:$O,$A8,Transactions!$B:$B,"Buy to close")-SUMIFS(Transactions!$E:$E,Transactions!$O:$O,$A8,Transactions!$B:$B,"Expired")-SUMIFS(Transactions!$E:$E,Transactions!$O:$O,$A8,Transactions!$B:$B,"Assigned"))>0,"Covered","Free"))) | P8: =IF(OR(I8="",G8<=0),"",CEILING(MAX(I8,N(L8)),IF(E8<50,0.5,IF(E8<200,1,5)))) | Q8: =IF(OR(N8="",G8<=0),"",IF(N8>=0,"",IF(COUNTIFS($B:$B,B8,$C:$C,">="&(TODAY()-30),$C:$C,"<="&TODAY(),$A:$A,"<>"&$A8)>0,"Loss sale now = wash sale","OK to harvest loss"))) | R8: =IF(OR($A8="",N(F8)<=0),"",SUMIFS(Transactions!$J:$J,Transactions!$O:$O,$A8,Transactions!$B:$B,"Sell shares")-E8*F8) | S8: =IF(OR($A8="",N(F8)<=0),"",_xlfn.MAXIFS(Transactions!$A:$A,Transactions!$O:$O,$A8,Transactions!$B:$B,"Sell shares")) | T8: =IF(OR($A8="",E8=""),"",E8*G8)
B9: =IF($A9="","",IFERROR(INDEX(Transactions!$C:$C,MATCH($A9,Transactions!$O:$O,0)),"")) | C9: =IF($A9="","",IF(COUNTIFS(Transactions!$O:$O,$A9,Transactions!$B:$B,"Buy shares")=0,"",_xlfn.MINIFS(Transactions!$A:$A,Transactions!$O:$O,$A9,Transactions!$B:$B,"Buy shares"))) | D9: =IF($A9="","",SUMIFS(Transactions!$E:$E,Transactions!$O:$O,$A9,Transactions!$B:$B,"Buy shares")) | E9: =IF($A9="","",IF(D9=0,"",-SUMIFS(Transactions!$J:$J,Transactions!$O:$O,$A9,Transactions!$B:$B,"Buy shares")/D9)) | F9: =IF($A9="","",-SUMIFS(Transactions!$E:$E,Transactions!$O:$O,$A9,Transactions!$B:$B,"Sell shares")) | G9: =IF($A9="","",D9-F9) | H9: =IF($A9="","",SUMIFS(Transactions!$J:$J,Transactions!$O:$O,$A9,Transactions!$B:$B,"Sell call")+SUMIFS(Transactions!$J:$J,Transactions!$O:$O,$A9,Transactions!$B:$B,"Buy to close")) | I9: =IF(OR($A9="",E9=""),"",E9-H9/D9) | J9: =IF($A9="","",IFERROR(INDEX(Positions!$K:$K,MATCH(B9,Positions!$B:$B,0)),"")) | L9: =IF($A9="","",IF(K9<>"",K9,J9)) | M9: =IF(OR($A9="",L9=""),"",L9*G9) | N9: =IF(OR(M9="",E9=""),"",(L9-E9)*G9) | O9: =IF($A9="","",IF(G9<=0,"Sold",IF((-SUMIFS(Transactions!$E:$E,Transactions!$O:$O,$A9,Transactions!$B:$B,"Sell call")-SUMIFS(Transactions!$E:$E,Transactions!$O:$O,$A9,Transactions!$B:$B,"Buy to close")-SUMIFS(Transactions!$E:$E,Transactions!$O:$O,$A9,Transactions!$B:$B,"Expired")-SUMIFS(Transactions!$E:$E,Transactions!$O:$O,$A9,Transactions!$B:$B,"Assigned"))>0,"Covered","Free"))) | P9: =IF(OR(I9="",G9<=0),"",CEILING(MAX(I9,N(L9)),IF(E9<50,0.5,IF(E9<200,1,5)))) | Q9: =IF(OR(N9="",G9<=0),"",IF(N9>=0,"",IF(COUNTIFS($B:$B,B9,$C:$C,">="&(TODAY()-30),$C:$C,"<="&TODAY(),$A:$A,"<>"&$A9)>0,"Loss sale now = wash sale","OK to harvest loss"))) | R9: =IF(OR($A9="",N(F9)<=0),"",SUMIFS(Transactions!$J:$J,Transactions!$O:$O,$A9,Transactions!$B:$B,"Sell shares")-E9*F9) | S9: =IF(OR($A9="",N(F9)<=0),"",_xlfn.MAXIFS(Transactions!$A:$A,Transactions!$O:$O,$A9,Transactions!$B:$B,"Sell shares")) | T9: =IF(OR($A9="",E9=""),"",E9*G9)
B10: =IF($A10="","",IFERROR(INDEX(Transactions!$C:$C,MATCH($A10,Transactions!$O:$O,0)),"")) | C10: =IF($A10="","",IF(COUNTIFS(Transactions!$O:$O,$A10,Transactions!$B:$B,"Buy shares")=0,"",_xlfn.MINIFS(Transactions!$A:$A,Transactions!$O:$O,$A10,Transactions!$B:$B,"Buy shares"))) | D10: =IF($A10="","",SUMIFS(Transactions!$E:$E,Transactions!$O:$O,$A10,Transactions!$B:$B,"Buy shares")) | E10: =IF($A10="","",IF(D10=0,"",-SUMIFS(Transactions!$J:$J,Transactions!$O:$O,$A10,Transactions!$B:$B,"Buy shares")/D10)) | F10: =IF($A10="","",-SUMIFS(Transactions!$E:$E,Transactions!$O:$O,$A10,Transactions!$B:$B,"Sell shares")) | G10: =IF($A10="","",D10-F10) | H10: =IF($A10="","",SUMIFS(Transactions!$J:$J,Transactions!$O:$O,$A10,Transactions!$B:$B,"Sell call")+SUMIFS(Transactions!$J:$J,Transactions!$O:$O,$A10,Transactions!$B:$B,"Buy to close")) | I10: =IF(OR($A10="",E10=""),"",E10-H10/D10) | J10: =IF($A10="","",IFERROR(INDEX(Positions!$K:$K,MATCH(B10,Positions!$B:$B,0)),"")) | L10: =IF($A10="","",IF(K10<>"",K10,J10)) | M10: =IF(OR($A10="",L10=""),"",L10*G10) | N10: =IF(OR(M10="",E10=""),"",(L10-E10)*G10) | O10: =IF($A10="","",IF(G10<=0,"Sold",IF((-SUMIFS(Transactions!$E:$E,Transactions!$O:$O,$A10,Transactions!$B:$B,"Sell call")-SUMIFS(Transactions!$E:$E,Transactions!$O:$O,$A10,Transactions!$B:$B,"Buy to close")-SUMIFS(Transactions!$E:$E,Transactions!$O:$O,$A10,Transactions!$B:$B,"Expired")-SUMIFS(Transactions!$E:$E,Transactions!$O:$O,$A10,Transactions!$B:$B,"Assigned"))>0,"Covered","Free"))) | P10: =IF(OR(I10="",G10<=0),"",CEILING(MAX(I10,N(L10)),IF(E10<50,0.5,IF(E10<200,1,5)))) | Q10: =IF(OR(N10="",G10<=0),"",IF(N10>=0,"",IF(COUNTIFS($B:$B,B10,$C:$C,">="&(TODAY()-30),$C:$C,"<="&TODAY(),$A:$A,"<>"&$A10)>0,"Loss sale now = wash sale","OK to harvest loss"))) | R10: =IF(OR($A10="",N(F10)<=0),"",SUMIFS(Transactions!$J:$J,Transactions!$O:$O,$A10,Transactions!$B:$B,"Sell shares")-E10*F10) | S10: =IF(OR($A10="",N(F10)<=0),"",_xlfn.MAXIFS(Transactions!$A:$A,Transactions!$O:$O,$A10,Transactions!$B:$B,"Sell shares")) | T10: =IF(OR($A10="",E10=""),"",E10*G10)
B11: =IF($A11="","",IFERROR(INDEX(Transactions!$C:$C,MATCH($A11,Transactions!$O:$O,0)),"")) | C11: =IF($A11="","",IF(COUNTIFS(Transactions!$O:$O,$A11,Transactions!$B:$B,"Buy shares")=0,"",_xlfn.MINIFS(Transactions!$A:$A,Transactions!$O:$O,$A11,Transactions!$B:$B,"Buy shares"))) | D11: =IF($A11="","",SUMIFS(Transactions!$E:$E,Transactions!$O:$O,$A11,Transactions!$B:$B,"Buy shares")) | E11: =IF($A11="","",IF(D11=0,"",-SUMIFS(Transactions!$J:$J,Transactions!$O:$O,$A11,Transactions!$B:$B,"Buy shares")/D11)) | F11: =IF($A11="","",-SUMIFS(Transactions!$E:$E,Transactions!$O:$O,$A11,Transactions!$B:$B,"Sell shares")) | G11: =IF($A11="","",D11-F11) | H11: =IF($A11="","",SUMIFS(Transactions!$J:$J,Transactions!$O:$O,$A11,Transactions!$B:$B,"Sell call")+SUMIFS(Transactions!$J:$J,Transactions!$O:$O,$A11,Transactions!$B:$B,"Buy to close")) | I11: =IF(OR($A11="",E11=""),"",E11-H11/D11) | J11: =IF($A11="","",IFERROR(INDEX(Positions!$K:$K,MATCH(B11,Positions!$B:$B,0)),"")) | L11: =IF($A11="","",IF(K11<>"",K11,J11)) | M11: =IF(OR($A11="",L11=""),"",L11*G11) | N11: =IF(OR(M11="",E11=""),"",(L11-E11)*G11) | O11: =IF($A11="","",IF(G11<=0,"Sold",IF((-SUMIFS(Transactions!$E:$E,Transactions!$O:$O,$A11,Transactions!$B:$B,"Sell call")-SUMIFS(Transactions!$E:$E,Transactions!$O:$O,$A11,Transactions!$B:$B,"Buy to close")-SUMIFS(Transactions!$E:$E,Transactions!$O:$O,$A11,Transactions!$B:$B,"Expired")-SUMIFS(Transactions!$E:$E,Transactions!$O:$O,$A11,Transactions!$B:$B,"Assigned"))>0,"Covered","Free"))) | P11: =IF(OR(I11="",G11<=0),"",CEILING(MAX(I11,N(L11)),IF(E11<50,0.5,IF(E11<200,1,5)))) | Q11: =IF(OR(N11="",G11<=0),"",IF(N11>=0,"",IF(COUNTIFS($B:$B,B11,$C:$C,">="&(TODAY()-30),$C:$C,"<="&TODAY(),$A:$A,"<>"&$A11)>0,"Loss sale now = wash sale","OK to harvest loss"))) | R11: =IF(OR($A11="",N(F11)<=0),"",SUMIFS(Transactions!$J:$J,Transactions!$O:$O,$A11,Transactions!$B:$B,"Sell shares")-E11*F11) | S11: =IF(OR($A11="",N(F11)<=0),"",_xlfn.MAXIFS(Transactions!$A:$A,Transactions!$O:$O,$A11,Transactions!$B:$B,"Sell shares")) | T11: =IF(OR($A11="",E11=""),"",E11*G11)
B12: =IF($A12="","",IFERROR(INDEX(Transactions!$C:$C,MATCH($A12,Transactions!$O:$O,0)),"")) | C12: =IF($A12="","",IF(COUNTIFS(Transactions!$O:$O,$A12,Transactions!$B:$B,"Buy shares")=0,"",_xlfn.MINIFS(Transactions!$A:$A,Transactions!$O:$O,$A12,Transactions!$B:$B,"Buy shares"))) | D12: =IF($A12="","",SUMIFS(Transactions!$E:$E,Transactions!$O:$O,$A12,Transactions!$B:$B,"Buy shares")) | E12: =IF($A12="","",IF(D12=0,"",-SUMIFS(Transactions!$J:$J,Transactions!$O:$O,$A12,Transactions!$B:$B,"Buy shares")/D12)) | F12: =IF($A12="","",-SUMIFS(Transactions!$E:$E,Transactions!$O:$O,$A12,Transactions!$B:$B,"Sell shares")) | G12: =IF($A12="","",D12-F12) | H12: =IF($A12="","",SUMIFS(Transactions!$J:$J,Transactions!$O:$O,$A12,Transactions!$B:$B,"Sell call")+SUMIFS(Transactions!$J:$J,Transactions!$O:$O,$A12,Transactions!$B:$B,"Buy to close")) | I12: =IF(OR($A12="",E12=""),"",E12-H12/D12) | J12: =IF($A12="","",IFERROR(INDEX(Positions!$K:$K,MATCH(B12,Positions!$B:$B,0)),"")) | L12: =IF($A12="","",IF(K12<>"",K12,J12)) | M12: =IF(OR($A12="",L12=""),"",L12*G12) | N12: =IF(OR(M12="",E12=""),"",(L12-E12)*G12) | O12: =IF($A12="","",IF(G12<=0,"Sold",IF((-SUMIFS(Transactions!$E:$E,Transactions!$O:$O,$A12,Transactions!$B:$B,"Sell call")-SUMIFS(Transactions!$E:$E,Transactions!$O:$O,$A12,Transactions!$B:$B,"Buy to close")-SUMIFS(Transactions!$E:$E,Transactions!$O:$O,$A12,Transactions!$B:$B,"Expired")-SUMIFS(Transactions!$E:$E,Transactions!$O:$O,$A12,Transactions!$B:$B,"Assigned"))>0,"Covered","Free"))) | P12: =IF(OR(I12="",G12<=0),"",CEILING(MAX(I12,N(L12)),IF(E12<50,0.5,IF(E12<200,1,5)))) | Q12: =IF(OR(N12="",G12<=0),"",IF(N12>=0,"",IF(COUNTIFS($B:$B,B12,$C:$C,">="&(TODAY()-30),$C:$C,"<="&TODAY(),$A:$A,"<>"&$A12)>0,"Loss sale now = wash sale","OK to harvest loss"))) | R12: =IF(OR($A12="",N(F12)<=0),"",SUMIFS(Transactions!$J:$J,Transactions!$O:$O,$A12,Transactions!$B:$B,"Sell shares")-E12*F12) | S12: =IF(OR($A12="",N(F12)<=0),"",_xlfn.MAXIFS(Transactions!$A:$A,Transactions!$O:$O,$A12,Transactions!$B:$B,"Sell shares")) | T12: =IF(OR($A12="",E12=""),"",E12*G12)
B13: =IF($A13="","",IFERROR(INDEX(Transactions!$C:$C,MATCH($A13,Transactions!$O:$O,0)),"")) | C13: =IF($A13="","",IF(COUNTIFS(Transactions!$O:$O,$A13,Transactions!$B:$B,"Buy shares")=0,"",_xlfn.MINIFS(Transactions!$A:$A,Transactions!$O:$O,$A13,Transactions!$B:$B,"Buy shares"))) | D13: =IF($A13="","",SUMIFS(Transactions!$E:$E,Transactions!$O:$O,$A13,Transactions!$B:$B,"Buy shares")) | E13: =IF($A13="","",IF(D13=0,"",-SUMIFS(Transactions!$J:$J,Transactions!$O:$O,$A13,Transactions!$B:$B,"Buy shares")/D13)) | F13: =IF($A13="","",-SUMIFS(Transactions!$E:$E,Transactions!$O:$O,$A13,Transactions!$B:$B,"Sell shares")) | G13: =IF($A13="","",D13-F13) | H13: =IF($A13="","",SUMIFS(Transactions!$J:$J,Transactions!$O:$O,$A13,Transactions!$B:$B,"Sell call")+SUMIFS(Transactions!$J:$J,Transactions!$O:$O,$A13,Transactions!$B:$B,"Buy to close")) | I13: =IF(OR($A13="",E13=""),"",E13-H13/D13) | J13: =IF($A13="","",IFERROR(INDEX(Positions!$K:$K,MATCH(B13,Positions!$B:$B,0)),"")) | L13: =IF($A13="","",IF(K13<>"",K13,J13)) | M13: =IF(OR($A13="",L13=""),"",L13*G13) | N13: =IF(OR(M13="",E13=""),"",(L13-E13)*G13) | O13: =IF($A13="","",IF(G13<=0,"Sold",IF((-SUMIFS(Transactions!$E:$E,Transactions!$O:$O,$A13,Transactions!$B:$B,"Sell call")-SUMIFS(Transactions!$E:$E,Transactions!$O:$O,$A13,Transactions!$B:$B,"Buy to close")-SUMIFS(Transactions!$E:$E,Transactions!$O:$O,$A13,Transactions!$B:$B,"Expired")-SUMIFS(Transactions!$E:$E,Transactions!$O:$O,$A13,Transactions!$B:$B,"Assigned"))>0,"Covered","Free"))) | P13: =IF(OR(I13="",G13<=0),"",CEILING(MAX(I13,N(L13)),IF(E13<50,0.5,IF(E13<200,1,5)))) | Q13: =IF(OR(N13="",G13<=0),"",IF(N13>=0,"",IF(COUNTIFS($B:$B,B13,$C:$C,">="&(TODAY()-30),$C:$C,"<="&TODAY(),$A:$A,"<>"&$A13)>0,"Loss sale now = wash sale","OK to harvest loss"))) | R13: =IF(OR($A13="",N(F13)<=0),"",SUMIFS(Transactions!$J:$J,Transactions!$O:$O,$A13,Transactions!$B:$B,"Sell shares")-E13*F13) | S13: =IF(OR($A13="",N(F13)<=0),"",_xlfn.MAXIFS(Transactions!$A:$A,Transactions!$O:$O,$A13,Transactions!$B:$B,"Sell shares")) | T13: =IF(OR($A13="",E13=""),"",E13*G13)
B14: =IF($A14="","",IFERROR(INDEX(Transactions!$C:$C,MATCH($A14,Transactions!$O:$O,0)),"")) | C14: =IF($A14="","",IF(COUNTIFS(Transactions!$O:$O,$A14,Transactions!$B:$B,"Buy shares")=0,"",_xlfn.MINIFS(Transactions!$A:$A,Transactions!$O:$O,$A14,Transactions!$B:$B,"Buy shares"))) | D14: =IF($A14="","",SUMIFS(Transactions!$E:$E,Transactions!$O:$O,$A14,Transactions!$B:$B,"Buy shares")) | E14: =IF($A14="","",IF(D14=0,"",-SUMIFS(Transactions!$J:$J,Transactions!$O:$O,$A14,Transactions!$B:$B,"Buy shares")/D14)) | F14: =IF($A14="","",-SUMIFS(Transactions!$E:$E,Transactions!$O:$O,$A14,Transactions!$B:$B,"Sell shares")) | G14: =IF($A14="","",D14-F14) | H14: =IF($A14="","",SUMIFS(Transactions!$J:$J,Transactions!$O:$O,$A14,Transactions!$B:$B,"Sell call")+SUMIFS(Transactions!$J:$J,Transactions!$O:$O,$A14,Transactions!$B:$B,"Buy to close")) | I14: =IF(OR($A14="",E14=""),"",E14-H14/D14) | J14: =IF($A14="","",IFERROR(INDEX(Positions!$K:$K,MATCH(B14,Positions!$B:$B,0)),"")) | L14: =IF($A14="","",IF(K14<>"",K14,J14)) | M14: =IF(OR($A14="",L14=""),"",L14*G14) | N14: =IF(OR(M14="",E14=""),"",(L14-E14)*G14) | O14: =IF($A14="","",IF(G14<=0,"Sold",IF((-SUMIFS(Transactions!$E:$E,Transactions!$O:$O,$A14,Transactions!$B:$B,"Sell call")-SUMIFS(Transactions!$E:$E,Transactions!$O:$O,$A14,Transactions!$B:$B,"Buy to close")-SUMIFS(Transactions!$E:$E,Transactions!$O:$O,$A14,Transactions!$B:$B,"Expired")-SUMIFS(Transactions!$E:$E,Transactions!$O:$O,$A14,Transactions!$B:$B,"Assigned"))>0,"Covered","Free"))) | P14: =IF(OR(I14="",G14<=0),"",CEILING(MAX(I14,N(L14)),IF(E14<50,0.5,IF(E14<200,1,5)))) | Q14: =IF(OR(N14="",G14<=0),"",IF(N14>=0,"",IF(COUNTIFS($B:$B,B14,$C:$C,">="&(TODAY()-30),$C:$C,"<="&TODAY(),$A:$A,"<>"&$A14)>0,"Loss sale now = wash sale","OK to harvest loss"))) | R14: =IF(OR($A14="",N(F14)<=0),"",SUMIFS(Transactions!$J:$J,Transactions!$O:$O,$A14,Transactions!$B:$B,"Sell shares")-E14*F14) | S14: =IF(OR($A14="",N(F14)<=0),"",_xlfn.MAXIFS(Transactions!$A:$A,Transactions!$O:$O,$A14,Transactions!$B:$B,"Sell shares")) | T14: =IF(OR($A14="",E14=""),"",E14*G14)
... B200: =IF($A200="","",IFERROR(INDEX(Transactions!$C:$C,MATCH($A200,Transactions!$O:$O,0)),"")) | C200: =IF($A200="","",IF(COUNTIFS(Transactions!$O:$O,$A200,Transactions!$B:$B,"Buy shares")=0,"",_xlfn.MINIFS(Transactions!$A:$A,Transactions!$O:$O,$A200,Transactions!$B:$B,"Buy shares"))) | D200: =IF($A200="","",SUMIFS(Transactions!$E:$E,Transactions!$O:$O,$A200,Transactions!$B:$B,"Buy shares")) | E200: =IF($A200="","",IF(D200=0,"",-SUMIFS(Transactions!$J:$J,Transactions!$O:$O,$A200,Transactions!$B:$B,"Buy shares")/D200)) | F200: =IF($A200="","",-SUMIFS(Transactions!$E:$E,Transactions!$O:$O,$A200,Transactions!$B:$B,"Sell shares")) | G200: =IF($A200="","",D200-F200) | H200: =IF($A200="","",SUMIFS(Transactions!$J:$J,Transactions!$O:$O,$A200,Transactions!$B:$B,"Sell call")+SUMIFS(Transactions!$J:$J,Transactions!$O:$O,$A200,Transactions!$B:$B,"Buy to close")) | I200: =IF(OR($A200="",E200=""),"",E200-H200/D200) | J200: =IF($A200="","",IFERROR(INDEX(Positions!$K:$K,MATCH(B200,Positions!$B:$B,0)),"")) | L200: =IF($A200="","",IF(K200<>"",K200,J200)) | M200: =IF(OR($A200="",L200=""),"",L200*G200) | N200: =IF(OR(M200="",E200=""),"",(L200-E200)*G200) | O200: =IF($A200="","",IF(G200<=0,"Sold",IF((-SUMIFS(Transactions!$E:$E,Transactions!$O:$O,$A200,Transactions!$B:$B,"Sell call")-SUMIFS(Transactions!$E:$E,Transactions!$O:$O,$A200,Transactions!$B:$B,"Buy to close")-SUMIFS(Transactions!$E:$E,Transactions!$O:$O,$A200,Transactions!$B:$B,"Expired")-SUMIFS(Transactions!$E:$E,Transactions!$O:$O,$A200,Transactions!$B:$B,"Assigned"))>0,"Covered","Free"))) | P200: =IF(OR(I200="",G200<=0),"",CEILING(MAX(I200,N(L200)),IF(E200<50,0.5,IF(E200<200,1,5)))) | Q200: =IF(OR(N200="",G200<=0),"",IF(N200>=0,"",IF(COUNTIFS($B:$B,B200,$C:$C,">="&(TODAY()-30),$C:$C,"<="&TODAY(),$A:$A,"<>"&$A200)>0,"Loss sale now = wash sale","OK to harvest loss"))) | R200: =IF(OR($A200="",N(F200)<=0),"",SUMIFS(Transactions!$J:$J,Transactions!$O:$O,$A200,Transactions!$B:$B,"Sell shares")-E200*F200) | S200: =IF(OR($A200="",N(F200)<=0),"",_xlfn.MAXIFS(Transactions!$A:$A,Transactions!$O:$O,$A200,Transactions!$B:$B,"Sell shares")) | T200: =IF(OR($A200="",E200=""),"",E200*G200)

Sheet Positions
A1: Position ID | B1: Symbol | C1: Status | D1: Contracts open | E1: Strike | F1: Expiry | G1: Shares covered | H1: Share cost | I1: Premium collected | J1: Buy backs paid | K1: Live stock price | L1: Live call mark | M1: GTC buy back | N1: Stoplight | O1: Last updated | P1: Buy back now | Q1: Premium kept if closed now | R1: Stock value now | S1: If closed now | T1: Health | U1: Closed on | V1: Realized premium | W1: Lot ID
A2: pfe-28-2026-10-16 | B2: =IF($A2="","",IFERROR(INDEX(Transactions!$C:$C,MATCH($A2,Transactions!$D:$D,0)),"")) -> PFE | C2: =IF($A2="","",IF(D2>0,"Open","Closed")) -> Open | D2: =IF($A2="","",-SUMIFS(Transactions!$E:$E,Transactions!$D:$D,$A2,Transactions!$B:$B,"Sell call")-SUMIFS(Transactions!$E:$E,Transactions!$D:$D,$A2,Transactions!$B:$B,"Buy to close")-SUMIFS(Transactions!$E:$E,Transactions!$D:$D,$A2,Transactions!$B:$B,"Expired")-SUMIFS(Transactions!$E:$E,Transactions!$D:$D,$A2,Transactions!$B:$B,"Assigned")) -> 1 | E2: =IF($A2="","",IFERROR(SUMIFS(Transactions!$F:$F,Transactions!$D:$D,$A2,Transactions!$B:$B,"Sell call")/COUNTIFS(Transactions!$D:$D,$A2,Transactions!$B:$B,"Sell call"),"")) -> 28 | F2: =IF($A2="","",IFERROR(SUMIFS(Transactions!$G:$G,Transactions!$D:$D,$A2,Transactions!$B:$B,"Sell call")/COUNTIFS(Transactions!$D:$D,$A2,Transactions!$B:$B,"Sell call"),"")) -> 46311 | G2: =IF($A2="","",-SUMIFS(Transactions!$E:$E,Transactions!$D:$D,$A2,Transactions!$B:$B,"Sell call")*100+SUMIFS(Transactions!$E:$E,Transactions!$D:$D,$A2,Transactions!$B:$B,"Sell shares")) -> 100 | H2: =IF($A2="","",IF(SUMIFS(Transactions!$J:$J,Transactions!$D:$D,$A2,Transactions!$B:$B,"Buy shares")<>0,-SUMIFS(Transactions!$J:$J,Transactions!$D:$D,$A2,Transactions!$B:$B,"Buy shares"),IFERROR(INDEX(Lots!$E:$E,MATCH($W2,Lots!$A:$A,0))*-SUMIFS(Transactions!$E:$E,Transactions!$D:$D,$A2,Transactions!$B:$B,"Sell call")*100,0))) -> 2780 | I2: =IF($A2="","",SUMIFS(Transactions!$J:$J,Transactions!$D:$D,$A2,Transactions!$B:$B,"Sell call")) -> 55 | J2: =IF($A2="","",-SUMIFS(Transactions!$J:$J,Transactions!$D:$D,$A2,Transactions!$B:$B,"Buy to close")) -> 0 | K2: 27.775 | L2: 0.57 | M2: 0.1 | N2: Yellow | O2: 2026-09-21 13:00 | P2: =IF(OR(C2<>"Open",L2=""),"",L2*100*D2) -> 57 | Q2: =IF(OR(C2<>"Open",P2=""),"",I2-J2-P2) -> -2 | R2: =IF(OR(C2<>"Open",K2=""),"",K2*G2) -> 2777.5 | S2: =IF(OR(R2="",Q2=""),"",R2-H2+Q2) -> -4.5 | T2: =IF(OR(R2="",Q2="",N(H2)=0),"",(R2+Q2)/H2) -> 0.99838129 | U2: =IF(C2<>"Closed","",_xlfn.MAXIFS(Transactions!$A:$A,Transactions!$D:$D,$A2)) | V2: =IF(C2<>"Closed","",I2-J2) | W2: =IF($A2="","",IFERROR(INDEX(Transactions!$O:$O,MATCH($A2,Transactions!$D:$D,0)),"")) -> pfe-a
B3: =IF($A3="","",IFERROR(INDEX(Transactions!$C:$C,MATCH($A3,Transactions!$D:$D,0)),"")) | C3: =IF($A3="","",IF(D3>0,"Open","Closed")) | D3: =IF($A3="","",-SUMIFS(Transactions!$E:$E,Transactions!$D:$D,$A3,Transactions!$B:$B,"Sell call")-SUMIFS(Transactions!$E:$E,Transactions!$D:$D,$A3,Transactions!$B:$B,"Buy to close")-SUMIFS(Transactions!$E:$E,Transactions!$D:$D,$A3,Transactions!$B:$B,"Expired")-SUMIFS(Transactions!$E:$E,Transactions!$D:$D,$A3,Transactions!$B:$B,"Assigned")) | E3: =IF($A3="","",IFERROR(SUMIFS(Transactions!$F:$F,Transactions!$D:$D,$A3,Transactions!$B:$B,"Sell call")/COUNTIFS(Transactions!$D:$D,$A3,Transactions!$B:$B,"Sell call"),"")) | F3: =IF($A3="","",IFERROR(SUMIFS(Transactions!$G:$G,Transactions!$D:$D,$A3,Transactions!$B:$B,"Sell call")/COUNTIFS(Transactions!$D:$D,$A3,Transactions!$B:$B,"Sell call"),"")) | G3: =IF($A3="","",-SUMIFS(Transactions!$E:$E,Transactions!$D:$D,$A3,Transactions!$B:$B,"Sell call")*100+SUMIFS(Transactions!$E:$E,Transactions!$D:$D,$A3,Transactions!$B:$B,"Sell shares")) | H3: =IF($A3="","",IF(SUMIFS(Transactions!$J:$J,Transactions!$D:$D,$A3,Transactions!$B:$B,"Buy shares")<>0,-SUMIFS(Transactions!$J:$J,Transactions!$D:$D,$A3,Transactions!$B:$B,"Buy shares"),IFERROR(INDEX(Lots!$E:$E,MATCH($W3,Lots!$A:$A,0))*-SUMIFS(Transactions!$E:$E,Transactions!$D:$D,$A3,Transactions!$B:$B,"Sell call")*100,0))) | I3: =IF($A3="","",SUMIFS(Transactions!$J:$J,Transactions!$D:$D,$A3,Transactions!$B:$B,"Sell call")) | J3: =IF($A3="","",-SUMIFS(Transactions!$J:$J,Transactions!$D:$D,$A3,Transactions!$B:$B,"Buy to close")) | P3: =IF(OR(C3<>"Open",L3=""),"",L3*100*D3) | Q3: =IF(OR(C3<>"Open",P3=""),"",I3-J3-P3) | R3: =IF(OR(C3<>"Open",K3=""),"",K3*G3) | S3: =IF(OR(R3="",Q3=""),"",R3-H3+Q3) | T3: =IF(OR(R3="",Q3="",N(H3)=0),"",(R3+Q3)/H3) | U3: =IF(C3<>"Closed","",_xlfn.MAXIFS(Transactions!$A:$A,Transactions!$D:$D,$A3)) | V3: =IF(C3<>"Closed","",I3-J3) | W3: =IF($A3="","",IFERROR(INDEX(Transactions!$O:$O,MATCH($A3,Transactions!$D:$D,0)),""))
B4: =IF($A4="","",IFERROR(INDEX(Transactions!$C:$C,MATCH($A4,Transactions!$D:$D,0)),"")) | C4: =IF($A4="","",IF(D4>0,"Open","Closed")) | D4: =IF($A4="","",-SUMIFS(Transactions!$E:$E,Transactions!$D:$D,$A4,Transactions!$B:$B,"Sell call")-SUMIFS(Transactions!$E:$E,Transactions!$D:$D,$A4,Transactions!$B:$B,"Buy to close")-SUMIFS(Transactions!$E:$E,Transactions!$D:$D,$A4,Transactions!$B:$B,"Expired")-SUMIFS(Transactions!$E:$E,Transactions!$D:$D,$A4,Transactions!$B:$B,"Assigned")) | E4: =IF($A4="","",IFERROR(SUMIFS(Transactions!$F:$F,Transactions!$D:$D,$A4,Transactions!$B:$B,"Sell call")/COUNTIFS(Transactions!$D:$D,$A4,Transactions!$B:$B,"Sell call"),"")) | F4: =IF($A4="","",IFERROR(SUMIFS(Transactions!$G:$G,Transactions!$D:$D,$A4,Transactions!$B:$B,"Sell call")/COUNTIFS(Transactions!$D:$D,$A4,Transactions!$B:$B,"Sell call"),"")) | G4: =IF($A4="","",-SUMIFS(Transactions!$E:$E,Transactions!$D:$D,$A4,Transactions!$B:$B,"Sell call")*100+SUMIFS(Transactions!$E:$E,Transactions!$D:$D,$A4,Transactions!$B:$B,"Sell shares")) | H4: =IF($A4="","",IF(SUMIFS(Transactions!$J:$J,Transactions!$D:$D,$A4,Transactions!$B:$B,"Buy shares")<>0,-SUMIFS(Transactions!$J:$J,Transactions!$D:$D,$A4,Transactions!$B:$B,"Buy shares"),IFERROR(INDEX(Lots!$E:$E,MATCH($W4,Lots!$A:$A,0))*-SUMIFS(Transactions!$E:$E,Transactions!$D:$D,$A4,Transactions!$B:$B,"Sell call")*100,0))) | I4: =IF($A4="","",SUMIFS(Transactions!$J:$J,Transactions!$D:$D,$A4,Transactions!$B:$B,"Sell call")) | J4: =IF($A4="","",-SUMIFS(Transactions!$J:$J,Transactions!$D:$D,$A4,Transactions!$B:$B,"Buy to close")) | P4: =IF(OR(C4<>"Open",L4=""),"",L4*100*D4) | Q4: =IF(OR(C4<>"Open",P4=""),"",I4-J4-P4) | R4: =IF(OR(C4<>"Open",K4=""),"",K4*G4) | S4: =IF(OR(R4="",Q4=""),"",R4-H4+Q4) | T4: =IF(OR(R4="",Q4="",N(H4)=0),"",(R4+Q4)/H4) | U4: =IF(C4<>"Closed","",_xlfn.MAXIFS(Transactions!$A:$A,Transactions!$D:$D,$A4)) | V4: =IF(C4<>"Closed","",I4-J4) | W4: =IF($A4="","",IFERROR(INDEX(Transactions!$O:$O,MATCH($A4,Transactions!$D:$D,0)),""))
B5: =IF($A5="","",IFERROR(INDEX(Transactions!$C:$C,MATCH($A5,Transactions!$D:$D,0)),"")) | C5: =IF($A5="","",IF(D5>0,"Open","Closed")) | D5: =IF($A5="","",-SUMIFS(Transactions!$E:$E,Transactions!$D:$D,$A5,Transactions!$B:$B,"Sell call")-SUMIFS(Transactions!$E:$E,Transactions!$D:$D,$A5,Transactions!$B:$B,"Buy to close")-SUMIFS(Transactions!$E:$E,Transactions!$D:$D,$A5,Transactions!$B:$B,"Expired")-SUMIFS(Transactions!$E:$E,Transactions!$D:$D,$A5,Transactions!$B:$B,"Assigned")) | E5: =IF($A5="","",IFERROR(SUMIFS(Transactions!$F:$F,Transactions!$D:$D,$A5,Transactions!$B:$B,"Sell call")/COUNTIFS(Transactions!$D:$D,$A5,Transactions!$B:$B,"Sell call"),"")) | F5: =IF($A5="","",IFERROR(SUMIFS(Transactions!$G:$G,Transactions!$D:$D,$A5,Transactions!$B:$B,"Sell call")/COUNTIFS(Transactions!$D:$D,$A5,Transactions!$B:$B,"Sell call"),"")) | G5: =IF($A5="","",-SUMIFS(Transactions!$E:$E,Transactions!$D:$D,$A5,Transactions!$B:$B,"Sell call")*100+SUMIFS(Transactions!$E:$E,Transactions!$D:$D,$A5,Transactions!$B:$B,"Sell shares")) | H5: =IF($A5="","",IF(SUMIFS(Transactions!$J:$J,Transactions!$D:$D,$A5,Transactions!$B:$B,"Buy shares")<>0,-SUMIFS(Transactions!$J:$J,Transactions!$D:$D,$A5,Transactions!$B:$B,"Buy shares"),IFERROR(INDEX(Lots!$E:$E,MATCH($W5,Lots!$A:$A,0))*-SUMIFS(Transactions!$E:$E,Transactions!$D:$D,$A5,Transactions!$B:$B,"Sell call")*100,0))) | I5: =IF($A5="","",SUMIFS(Transactions!$J:$J,Transactions!$D:$D,$A5,Transactions!$B:$B,"Sell call")) | J5: =IF($A5="","",-SUMIFS(Transactions!$J:$J,Transactions!$D:$D,$A5,Transactions!$B:$B,"Buy to close")) | P5: =IF(OR(C5<>"Open",L5=""),"",L5*100*D5) | Q5: =IF(OR(C5<>"Open",P5=""),"",I5-J5-P5) | R5: =IF(OR(C5<>"Open",K5=""),"",K5*G5) | S5: =IF(OR(R5="",Q5=""),"",R5-H5+Q5) | T5: =IF(OR(R5="",Q5="",N(H5)=0),"",(R5+Q5)/H5) | U5: =IF(C5<>"Closed","",_xlfn.MAXIFS(Transactions!$A:$A,Transactions!$D:$D,$A5)) | V5: =IF(C5<>"Closed","",I5-J5) | W5: =IF($A5="","",IFERROR(INDEX(Transactions!$O:$O,MATCH($A5,Transactions!$D:$D,0)),""))
B6: =IF($A6="","",IFERROR(INDEX(Transactions!$C:$C,MATCH($A6,Transactions!$D:$D,0)),"")) | C6: =IF($A6="","",IF(D6>0,"Open","Closed")) | D6: =IF($A6="","",-SUMIFS(Transactions!$E:$E,Transactions!$D:$D,$A6,Transactions!$B:$B,"Sell call")-SUMIFS(Transactions!$E:$E,Transactions!$D:$D,$A6,Transactions!$B:$B,"Buy to close")-SUMIFS(Transactions!$E:$E,Transactions!$D:$D,$A6,Transactions!$B:$B,"Expired")-SUMIFS(Transactions!$E:$E,Transactions!$D:$D,$A6,Transactions!$B:$B,"Assigned")) | E6: =IF($A6="","",IFERROR(SUMIFS(Transactions!$F:$F,Transactions!$D:$D,$A6,Transactions!$B:$B,"Sell call")/COUNTIFS(Transactions!$D:$D,$A6,Transactions!$B:$B,"Sell call"),"")) | F6: =IF($A6="","",IFERROR(SUMIFS(Transactions!$G:$G,Transactions!$D:$D,$A6,Transactions!$B:$B,"Sell call")/COUNTIFS(Transactions!$D:$D,$A6,Transactions!$B:$B,"Sell call"),"")) | G6: =IF($A6="","",-SUMIFS(Transactions!$E:$E,Transactions!$D:$D,$A6,Transactions!$B:$B,"Sell call")*100+SUMIFS(Transactions!$E:$E,Transactions!$D:$D,$A6,Transactions!$B:$B,"Sell shares")) | H6: =IF($A6="","",IF(SUMIFS(Transactions!$J:$J,Transactions!$D:$D,$A6,Transactions!$B:$B,"Buy shares")<>0,-SUMIFS(Transactions!$J:$J,Transactions!$D:$D,$A6,Transactions!$B:$B,"Buy shares"),IFERROR(INDEX(Lots!$E:$E,MATCH($W6,Lots!$A:$A,0))*-SUMIFS(Transactions!$E:$E,Transactions!$D:$D,$A6,Transactions!$B:$B,"Sell call")*100,0))) | I6: =IF($A6="","",SUMIFS(Transactions!$J:$J,Transactions!$D:$D,$A6,Transactions!$B:$B,"Sell call")) | J6: =IF($A6="","",-SUMIFS(Transactions!$J:$J,Transactions!$D:$D,$A6,Transactions!$B:$B,"Buy to close")) | P6: =IF(OR(C6<>"Open",L6=""),"",L6*100*D6) | Q6: =IF(OR(C6<>"Open",P6=""),"",I6-J6-P6) | R6: =IF(OR(C6<>"Open",K6=""),"",K6*G6) | S6: =IF(OR(R6="",Q6=""),"",R6-H6+Q6) | T6: =IF(OR(R6="",Q6="",N(H6)=0),"",(R6+Q6)/H6) | U6: =IF(C6<>"Closed","",_xlfn.MAXIFS(Transactions!$A:$A,Transactions!$D:$D,$A6)) | V6: =IF(C6<>"Closed","",I6-J6) | W6: =IF($A6="","",IFERROR(INDEX(Transactions!$O:$O,MATCH($A6,Transactions!$D:$D,0)),""))
B7: =IF($A7="","",IFERROR(INDEX(Transactions!$C:$C,MATCH($A7,Transactions!$D:$D,0)),"")) | C7: =IF($A7="","",IF(D7>0,"Open","Closed")) | D7: =IF($A7="","",-SUMIFS(Transactions!$E:$E,Transactions!$D:$D,$A7,Transactions!$B:$B,"Sell call")-SUMIFS(Transactions!$E:$E,Transactions!$D:$D,$A7,Transactions!$B:$B,"Buy to close")-SUMIFS(Transactions!$E:$E,Transactions!$D:$D,$A7,Transactions!$B:$B,"Expired")-SUMIFS(Transactions!$E:$E,Transactions!$D:$D,$A7,Transactions!$B:$B,"Assigned")) | E7: =IF($A7="","",IFERROR(SUMIFS(Transactions!$F:$F,Transactions!$D:$D,$A7,Transactions!$B:$B,"Sell call")/COUNTIFS(Transactions!$D:$D,$A7,Transactions!$B:$B,"Sell call"),"")) | F7: =IF($A7="","",IFERROR(SUMIFS(Transactions!$G:$G,Transactions!$D:$D,$A7,Transactions!$B:$B,"Sell call")/COUNTIFS(Transactions!$D:$D,$A7,Transactions!$B:$B,"Sell call"),"")) | G7: =IF($A7="","",-SUMIFS(Transactions!$E:$E,Transactions!$D:$D,$A7,Transactions!$B:$B,"Sell call")*100+SUMIFS(Transactions!$E:$E,Transactions!$D:$D,$A7,Transactions!$B:$B,"Sell shares")) | H7: =IF($A7="","",IF(SUMIFS(Transactions!$J:$J,Transactions!$D:$D,$A7,Transactions!$B:$B,"Buy shares")<>0,-SUMIFS(Transactions!$J:$J,Transactions!$D:$D,$A7,Transactions!$B:$B,"Buy shares"),IFERROR(INDEX(Lots!$E:$E,MATCH($W7,Lots!$A:$A,0))*-SUMIFS(Transactions!$E:$E,Transactions!$D:$D,$A7,Transactions!$B:$B,"Sell call")*100,0))) | I7: =IF($A7="","",SUMIFS(Transactions!$J:$J,Transactions!$D:$D,$A7,Transactions!$B:$B,"Sell call")) | J7: =IF($A7="","",-SUMIFS(Transactions!$J:$J,Transactions!$D:$D,$A7,Transactions!$B:$B,"Buy to close")) | P7: =IF(OR(C7<>"Open",L7=""),"",L7*100*D7) | Q7: =IF(OR(C7<>"Open",P7=""),"",I7-J7-P7) | R7: =IF(OR(C7<>"Open",K7=""),"",K7*G7) | S7: =IF(OR(R7="",Q7=""),"",R7-H7+Q7) | T7: =IF(OR(R7="",Q7="",N(H7)=0),"",(R7+Q7)/H7) | U7: =IF(C7<>"Closed","",_xlfn.MAXIFS(Transactions!$A:$A,Transactions!$D:$D,$A7)) | V7: =IF(C7<>"Closed","",I7-J7) | W7: =IF($A7="","",IFERROR(INDEX(Transactions!$O:$O,MATCH($A7,Transactions!$D:$D,0)),""))
B8: =IF($A8="","",IFERROR(INDEX(Transactions!$C:$C,MATCH($A8,Transactions!$D:$D,0)),"")) | C8: =IF($A8="","",IF(D8>0,"Open","Closed")) | D8: =IF($A8="","",-SUMIFS(Transactions!$E:$E,Transactions!$D:$D,$A8,Transactions!$B:$B,"Sell call")-SUMIFS(Transactions!$E:$E,Transactions!$D:$D,$A8,Transactions!$B:$B,"Buy to close")-SUMIFS(Transactions!$E:$E,Transactions!$D:$D,$A8,Transactions!$B:$B,"Expired")-SUMIFS(Transactions!$E:$E,Transactions!$D:$D,$A8,Transactions!$B:$B,"Assigned")) | E8: =IF($A8="","",IFERROR(SUMIFS(Transactions!$F:$F,Transactions!$D:$D,$A8,Transactions!$B:$B,"Sell call")/COUNTIFS(Transactions!$D:$D,$A8,Transactions!$B:$B,"Sell call"),"")) | F8: =IF($A8="","",IFERROR(SUMIFS(Transactions!$G:$G,Transactions!$D:$D,$A8,Transactions!$B:$B,"Sell call")/COUNTIFS(Transactions!$D:$D,$A8,Transactions!$B:$B,"Sell call"),"")) | G8: =IF($A8="","",-SUMIFS(Transactions!$E:$E,Transactions!$D:$D,$A8,Transactions!$B:$B,"Sell call")*100+SUMIFS(Transactions!$E:$E,Transactions!$D:$D,$A8,Transactions!$B:$B,"Sell shares")) | H8: =IF($A8="","",IF(SUMIFS(Transactions!$J:$J,Transactions!$D:$D,$A8,Transactions!$B:$B,"Buy shares")<>0,-SUMIFS(Transactions!$J:$J,Transactions!$D:$D,$A8,Transactions!$B:$B,"Buy shares"),IFERROR(INDEX(Lots!$E:$E,MATCH($W8,Lots!$A:$A,0))*-SUMIFS(Transactions!$E:$E,Transactions!$D:$D,$A8,Transactions!$B:$B,"Sell call")*100,0))) | I8: =IF($A8="","",SUMIFS(Transactions!$J:$J,Transactions!$D:$D,$A8,Transactions!$B:$B,"Sell call")) | J8: =IF($A8="","",-SUMIFS(Transactions!$J:$J,Transactions!$D:$D,$A8,Transactions!$B:$B,"Buy to close")) | P8: =IF(OR(C8<>"Open",L8=""),"",L8*100*D8) | Q8: =IF(OR(C8<>"Open",P8=""),"",I8-J8-P8) | R8: =IF(OR(C8<>"Open",K8=""),"",K8*G8) | S8: =IF(OR(R8="",Q8=""),"",R8-H8+Q8) | T8: =IF(OR(R8="",Q8="",N(H8)=0),"",(R8+Q8)/H8) | U8: =IF(C8<>"Closed","",_xlfn.MAXIFS(Transactions!$A:$A,Transactions!$D:$D,$A8)) | V8: =IF(C8<>"Closed","",I8-J8) | W8: =IF($A8="","",IFERROR(INDEX(Transactions!$O:$O,MATCH($A8,Transactions!$D:$D,0)),""))
B9: =IF($A9="","",IFERROR(INDEX(Transactions!$C:$C,MATCH($A9,Transactions!$D:$D,0)),"")) | C9: =IF($A9="","",IF(D9>0,"Open","Closed")) | D9: =IF($A9="","",-SUMIFS(Transactions!$E:$E,Transactions!$D:$D,$A9,Transactions!$B:$B,"Sell call")-SUMIFS(Transactions!$E:$E,Transactions!$D:$D,$A9,Transactions!$B:$B,"Buy to close")-SUMIFS(Transactions!$E:$E,Transactions!$D:$D,$A9,Transactions!$B:$B,"Expired")-SUMIFS(Transactions!$E:$E,Transactions!$D:$D,$A9,Transactions!$B:$B,"Assigned")) | E9: =IF($A9="","",IFERROR(SUMIFS(Transactions!$F:$F,Transactions!$D:$D,$A9,Transactions!$B:$B,"Sell call")/COUNTIFS(Transactions!$D:$D,$A9,Transactions!$B:$B,"Sell call"),"")) | F9: =IF($A9="","",IFERROR(SUMIFS(Transactions!$G:$G,Transactions!$D:$D,$A9,Transactions!$B:$B,"Sell call")/COUNTIFS(Transactions!$D:$D,$A9,Transactions!$B:$B,"Sell call"),"")) | G9: =IF($A9="","",-SUMIFS(Transactions!$E:$E,Transactions!$D:$D,$A9,Transactions!$B:$B,"Sell call")*100+SUMIFS(Transactions!$E:$E,Transactions!$D:$D,$A9,Transactions!$B:$B,"Sell shares")) | H9: =IF($A9="","",IF(SUMIFS(Transactions!$J:$J,Transactions!$D:$D,$A9,Transactions!$B:$B,"Buy shares")<>0,-SUMIFS(Transactions!$J:$J,Transactions!$D:$D,$A9,Transactions!$B:$B,"Buy shares"),IFERROR(INDEX(Lots!$E:$E,MATCH($W9,Lots!$A:$A,0))*-SUMIFS(Transactions!$E:$E,Transactions!$D:$D,$A9,Transactions!$B:$B,"Sell call")*100,0))) | I9: =IF($A9="","",SUMIFS(Transactions!$J:$J,Transactions!$D:$D,$A9,Transactions!$B:$B,"Sell call")) | J9: =IF($A9="","",-SUMIFS(Transactions!$J:$J,Transactions!$D:$D,$A9,Transactions!$B:$B,"Buy to close")) | P9: =IF(OR(C9<>"Open",L9=""),"",L9*100*D9) | Q9: =IF(OR(C9<>"Open",P9=""),"",I9-J9-P9) | R9: =IF(OR(C9<>"Open",K9=""),"",K9*G9) | S9: =IF(OR(R9="",Q9=""),"",R9-H9+Q9) | T9: =IF(OR(R9="",Q9="",N(H9)=0),"",(R9+Q9)/H9) | U9: =IF(C9<>"Closed","",_xlfn.MAXIFS(Transactions!$A:$A,Transactions!$D:$D,$A9)) | V9: =IF(C9<>"Closed","",I9-J9) | W9: =IF($A9="","",IFERROR(INDEX(Transactions!$O:$O,MATCH($A9,Transactions!$D:$D,0)),""))
B10: =IF($A10="","",IFERROR(INDEX(Transactions!$C:$C,MATCH($A10,Transactions!$D:$D,0)),"")) | C10: =IF($A10="","",IF(D10>0,"Open","Closed")) | D10: =IF($A10="","",-SUMIFS(Transactions!$E:$E,Transactions!$D:$D,$A10,Transactions!$B:$B,"Sell call")-SUMIFS(Transactions!$E:$E,Transactions!$D:$D,$A10,Transactions!$B:$B,"Buy to close")-SUMIFS(Transactions!$E:$E,Transactions!$D:$D,$A10,Transactions!$B:$B,"Expired")-SUMIFS(Transactions!$E:$E,Transactions!$D:$D,$A10,Transactions!$B:$B,"Assigned")) | E10: =IF($A10="","",IFERROR(SUMIFS(Transactions!$F:$F,Transactions!$D:$D,$A10,Transactions!$B:$B,"Sell call")/COUNTIFS(Transactions!$D:$D,$A10,Transactions!$B:$B,"Sell call"),"")) | F10: =IF($A10="","",IFERROR(SUMIFS(Transactions!$G:$G,Transactions!$D:$D,$A10,Transactions!$B:$B,"Sell call")/COUNTIFS(Transactions!$D:$D,$A10,Transactions!$B:$B,"Sell call"),"")) | G10: =IF($A10="","",-SUMIFS(Transactions!$E:$E,Transactions!$D:$D,$A10,Transactions!$B:$B,"Sell call")*100+SUMIFS(Transactions!$E:$E,Transactions!$D:$D,$A10,Transactions!$B:$B,"Sell shares")) | H10: =IF($A10="","",IF(SUMIFS(Transactions!$J:$J,Transactions!$D:$D,$A10,Transactions!$B:$B,"Buy shares")<>0,-SUMIFS(Transactions!$J:$J,Transactions!$D:$D,$A10,Transactions!$B:$B,"Buy shares"),IFERROR(INDEX(Lots!$E:$E,MATCH($W10,Lots!$A:$A,0))*-SUMIFS(Transactions!$E:$E,Transactions!$D:$D,$A10,Transactions!$B:$B,"Sell call")*100,0))) | I10: =IF($A10="","",SUMIFS(Transactions!$J:$J,Transactions!$D:$D,$A10,Transactions!$B:$B,"Sell call")) | J10: =IF($A10="","",-SUMIFS(Transactions!$J:$J,Transactions!$D:$D,$A10,Transactions!$B:$B,"Buy to close")) | P10: =IF(OR(C10<>"Open",L10=""),"",L10*100*D10) | Q10: =IF(OR(C10<>"Open",P10=""),"",I10-J10-P10) | R10: =IF(OR(C10<>"Open",K10=""),"",K10*G10) | S10: =IF(OR(R10="",Q10=""),"",R10-H10+Q10) | T10: =IF(OR(R10="",Q10="",N(H10)=0),"",(R10+Q10)/H10) | U10: =IF(C10<>"Closed","",_xlfn.MAXIFS(Transactions!$A:$A,Transactions!$D:$D,$A10)) | V10: =IF(C10<>"Closed","",I10-J10) | W10: =IF($A10="","",IFERROR(INDEX(Transactions!$O:$O,MATCH($A10,Transactions!$D:$D,0)),""))
B11: =IF($A11="","",IFERROR(INDEX(Transactions!$C:$C,MATCH($A11,Transactions!$D:$D,0)),"")) | C11: =IF($A11="","",IF(D11>0,"Open","Closed")) | D11: =IF($A11="","",-SUMIFS(Transactions!$E:$E,Transactions!$D:$D,$A11,Transactions!$B:$B,"Sell call")-SUMIFS(Transactions!$E:$E,Transactions!$D:$D,$A11,Transactions!$B:$B,"Buy to close")-SUMIFS(Transactions!$E:$E,Transactions!$D:$D,$A11,Transactions!$B:$B,"Expired")-SUMIFS(Transactions!$E:$E,Transactions!$D:$D,$A11,Transactions!$B:$B,"Assigned")) | E11: =IF($A11="","",IFERROR(SUMIFS(Transactions!$F:$F,Transactions!$D:$D,$A11,Transactions!$B:$B,"Sell call")/COUNTIFS(Transactions!$D:$D,$A11,Transactions!$B:$B,"Sell call"),"")) | F11: =IF($A11="","",IFERROR(SUMIFS(Transactions!$G:$G,Transactions!$D:$D,$A11,Transactions!$B:$B,"Sell call")/COUNTIFS(Transactions!$D:$D,$A11,Transactions!$B:$B,"Sell call"),"")) | G11: =IF($A11="","",-SUMIFS(Transactions!$E:$E,Transactions!$D:$D,$A11,Transactions!$B:$B,"Sell call")*100+SUMIFS(Transactions!$E:$E,Transactions!$D:$D,$A11,Transactions!$B:$B,"Sell shares")) | H11: =IF($A11="","",IF(SUMIFS(Transactions!$J:$J,Transactions!$D:$D,$A11,Transactions!$B:$B,"Buy shares")<>0,-SUMIFS(Transactions!$J:$J,Transactions!$D:$D,$A11,Transactions!$B:$B,"Buy shares"),IFERROR(INDEX(Lots!$E:$E,MATCH($W11,Lots!$A:$A,0))*-SUMIFS(Transactions!$E:$E,Transactions!$D:$D,$A11,Transactions!$B:$B,"Sell call")*100,0))) | I11: =IF($A11="","",SUMIFS(Transactions!$J:$J,Transactions!$D:$D,$A11,Transactions!$B:$B,"Sell call")) | J11: =IF($A11="","",-SUMIFS(Transactions!$J:$J,Transactions!$D:$D,$A11,Transactions!$B:$B,"Buy to close")) | P11: =IF(OR(C11<>"Open",L11=""),"",L11*100*D11) | Q11: =IF(OR(C11<>"Open",P11=""),"",I11-J11-P11) | R11: =IF(OR(C11<>"Open",K11=""),"",K11*G11) | S11: =IF(OR(R11="",Q11=""),"",R11-H11+Q11) | T11: =IF(OR(R11="",Q11="",N(H11)=0),"",(R11+Q11)/H11) | U11: =IF(C11<>"Closed","",_xlfn.MAXIFS(Transactions!$A:$A,Transactions!$D:$D,$A11)) | V11: =IF(C11<>"Closed","",I11-J11) | W11: =IF($A11="","",IFERROR(INDEX(Transactions!$O:$O,MATCH($A11,Transactions!$D:$D,0)),""))
